import { throwError, throwCustomError, resolveValue, MyAwesomeError, rejectCustomError } from './index';

describe('resolveValue', () => {
  test('should resolve provided value', async () => {
    const testValue = 'test value';
    await expect(resolveValue(testValue)).resolves.toBe(testValue);
  });
});

describe('throwError', () => {
  test('should throw error with provided message', () => {
    const errorMessage = 'Test error message';
    expect(() => throwError(errorMessage)).toThrow(errorMessage);
  });

  test('should throw error with default message if message is not provided', () => {
    expect(() => throwError()).toThrow('Oops!');
  });
});

describe('throwCustomError', () => {
  test('should throw custom error', () => {
    expect(() => throwCustomError()).toThrow(MyAwesomeError);
  });

  test('should include custom error message', () => {
    try {
      throwCustomError();
    } catch (error) {
      expect(error).toBeInstanceOf(MyAwesomeError);
    }
  });
});

describe('rejectCustomError', () => {
  test('should reject custom error', async () => {
    await expect(rejectCustomError()).rejects.toThrow(MyAwesomeError);
  });

  test('should reject with custom error message', async () => {
    await expect(rejectCustomError()).rejects.toThrow('This is my awesome custom error!');
  });
});
